<mujoco model="humanoid">

  <statistic extent="2" center="0 0 1"/>

  <option timestep="0.00555"/>

  <default>
    <motor ctrlrange="-1 1" ctrllimited="true"/>
    <default class="body">
      <geom type="capsule" condim="1" friction="1.0 0.05 0.05" solimp=".9 .99 .003" solref=".015 1"/>
      <joint type="hinge" damping="0.1" stiffness="5" armature=".007" limited="true" solimplimit="0 .99 .01"/>
      <site size=".04" group="3"/>
      <default class="force-torque">
        <site type="box" size=".01 .01 .02" rgba="1 0 0 1" />
      </default>
      <default class="touch">
        <site type="capsule" rgba="0 0 1 .3"/>
      </default>
    </default>
  </default>

  <asset>
    <mesh file="../smpl_foot_meshes/left_foot.obj" name="left_foot_mesh"/>
    <mesh file="../smpl_foot_meshes/right_foot.obj" name="right_foot_mesh"/>
  </asset>

  <worldbody>
    <geom name="floor" type="plane" conaffinity="1" size="100 100 .2" material="grid"/>
    <body name="pelvis" pos="0 0 1" childclass="body">
      <freejoint name="root"/>
      <geom name="pelvis" type="sphere" pos="0 0 0.0" size=".0942" density="2226"/>
      <geom name="upper_waist" type="sphere" pos="0 0 0.17" size="0.078" density="2226"/>

      <body name="torso" pos="0 0 0.236151">
        <light name="top" pos="0 0 2" mode="trackcom"/>
        <camera name="back" pos="-3 0 1" xyaxes="0 -1 0 1 0 2" mode="trackcom"/>
        <camera name="side" pos="0 -3 1" xyaxes="1 0 0 0 1 2" mode="trackcom"/>
        <joint name="abdomen_x" pos="0 0 0" axis="1 0 0" range="-60 60" stiffness="1000" damping="100" armature=".02"/>
        <joint name="abdomen_y" pos="0 0 0" axis="0 1 0" range="-60 90" stiffness="1000" damping="100" armature=".02"/>
        <joint name="abdomen_z" pos="0 0 0" axis="0 0 1" range="-50 50" stiffness="1000" damping="100" armature=".02"/>
        <geom name="torso" type="sphere" pos="0 0 0.12" size="0.11" density="1794"/>

        <geom name="right_clavicle" fromto="-0.0060125 -0.0457775 0.2287955 -0.016835 -0.128177 0.2376182" size=".045" density="1100"/>
        <geom name="left_clavicle" fromto="-0.0060125 0.0457775 0.2287955 -0.016835 0.128177 0.2376182" size=".045" density="1100"/>

        <body name="head" pos="0 0 0.223894">
          <joint name="neck_x" axis="1 0 0" range="-50 50" stiffness="100" damping="10" armature=".01"/>
          <joint name="neck_y" axis="0 1 0" range="-40 60" stiffness="100" damping="10" armature=".01"/>
          <joint name="neck_z" axis="0 0 1" range="-45 45" stiffness="100" damping="10" armature=".01"/>
          <geom name="head" type="sphere" pos="0 0 0.175" size="0.095" density="1081"/>
          <camera name="egocentric" pos=".103 0 0.175" xyaxes="0 -1 0 .1 0 1" fovy="80"/>
        </body>

        <body name="right_upper_arm" pos="-0.02405 -0.18311 0.24350">
          <joint name="right_shoulder_x" axis="1 0 0" range="-180 45" stiffness="400" damping="40" armature=".02"/>
          <joint name="right_shoulder_y" axis="0 1 0" range="-180 60" stiffness="400" damping="40" armature=".02"/>
          <joint name="right_shoulder_z" axis="0 0 1"  range="-90 90" stiffness="400" damping="40" armature=".02"/>
          <geom name="right_upper_arm" fromto="0 0 -0.05 0 0 -0.23" size=".045" density="982"/>

          <body name="right_lower_arm" pos="0 0 -0.274788">
            <joint name="right_elbow" axis="0 1 0" range="-160 0" stiffness="300" damping="30" armature=".01"/>
            <geom name="right_lower_arm" fromto="0 0 -0.0525 0 0 -0.1875" size="0.04" density="1056"/>

            <body name="right_hand" pos="0 0 -0.258947">
              <geom name="right_hand" type="sphere" size=".04" density="1865"/>
            </body>
          </body>
        </body>

        <body name="left_upper_arm" pos="-0.02405 0.18311 0.24350">
          <joint name="left_shoulder_x" axis="1 0 0" range="-45 180" stiffness="400" damping="40" armature=".02"/>
          <joint name="left_shoulder_y" axis="0 1 0" range="-180 60" stiffness="400" damping="40" armature=".02"/>
          <joint name="left_shoulder_z" axis="0 0 1"  range="-90 90" stiffness="400" damping="40" armature=".02"/>
          <geom name="left_upper_arm" fromto="0 0 -0.05 0 0 -0.23" size="0.045" density="982"/>

          <body name="left_lower_arm" pos="0 0 -0.274788">
            <joint name="left_elbow" axis="0 1 0" range="-160 0" stiffness="300" damping="30" armature=".01"/>
            <geom name="left_lower_arm" fromto="0 0 -0.0525 0 0 -0.1875" size="0.04" density="1056"/>

            <body name="left_hand" pos="0 0 -0.258947">
              <geom name="left_hand" type="sphere" size=".04" density="1865"/>
            </body>
          </body>
        </body>
      </body>

      <body name="right_thigh" pos="-0.0043 -0.0677 -0.0905">
        <joint name="right_hip_x" axis="1 0 0" range="-60 15" stiffness="500" damping="50" armature=".02"/>
        <joint name="right_hip_y" axis="0 1 0" range="-140 60" stiffness="500" damping="50" armature=".02"/>
        <joint name="right_hip_z" axis="0 0 1" range="-60 35" stiffness="500" damping="50" armature=".02"/>
        <geom name="right_thigh" fromto="-0.0009 -0.0038 -0.0383 -0.0080 -0.0345 -0.3443" size="0.055" density="1269"/>

        <body name="right_shin" pos="-0.0089 -0.0383 -0.3826">
          <joint name="right_knee_x" pos="0 0 0" axis="1 0 0" range="-5.6250 5.6250" stiffness="500" damping="50" armature=".02"/>
          <joint name="right_knee_y" pos="0 0 0" axis="0 1 0" range="0 160" stiffness="500" damping="50" armature=".02"/>
          <joint name="right_knee_z" pos="0 0 0" axis="0 0 1" range="-5.6250 5.6250" stiffness="500" damping="50" armature=".02"/>
          <geom name="right_shin" fromto="-0.0085 0.0032 -0.0797 -0.0338 0.0126 -0.3187"  size=".05" density="1014"/>

          <body name="right_foot" pos="-0.0423 0.0158 -0.3984">
            <joint name="right_ankle_x" pos="0 0 0" axis="1 0 0" range="-30 30" stiffness="400" damping="40" armature=".01"/>
            <joint name="right_ankle_y" pos="0 0 0" axis="0 1 0" range="-55 55" stiffness="400" damping="40" armature=".01"/>
            <joint name="right_ankle_z" pos="0 0 0" axis="0 0 1" range="-40 40" stiffness="400" damping="40" armature=".01"/>
            <!-- <geom name="right_foot" type="box" pos="0.0617 -0.0127 -0.0241" size="0.0865 0.0483 0.0208" density="1141"/> -->
            <!-- <geom name="right_foot_toe" type="box" pos="0.186 -0.0127 -0.0232" size="0.0195 0.0479 0.0216" density="1141"/> -->
            <!-- <geom name="right_foot" type="mesh" mesh="right_foot_mesh" pos="0.0000 0.0000 0.0000" density="1141"/> -->
            <geom name="right_foot" type="box" pos="0.04840836 -0.02035321 -0.02758488"  quat="0.99958537 0 0.02879395 0" size="0.10862014 0.04908623 0.03632472" density="1141"/>
          </body>
        </body>
      </body>

      <body name="left_thigh" pos="-0.0068 0.0695 -0.0914">
        <joint name="left_hip_x" axis="1 0 0" range="-15 60" stiffness="500" damping="50" armature=".02"/>
        <joint name="left_hip_y" axis="0 1 0" range="-140 60" stiffness="500" damping="50" armature=".02"/>
        <joint name="left_hip_z" axis="0 0 1" range="-35 60" stiffness="500" damping="50" armature=".02"/>
        <geom name="left_thigh" fromto="-0.0004 0.0034 -0.0375 -0.0040 0.0308 -0.3377" size=".055" density="1269"/>

        <body name="left_shin" pos="-0.0045 0.0343 -0.3752">
          <joint name="left_knee_x" pos="0 0 0" axis="1 0 0" range="-5.6250 5.6250" stiffness="500" damping="50" armature=".02"/>
          <joint name="left_knee_y" pos="0 0 0" axis="0 1 0" range="0 160" stiffness="500" damping="50" armature=".02"/>
          <joint name="left_knee_z" pos="0 0 0" axis="0 0 1" range="-5.6250 5.6250" stiffness="500" damping="50" armature=".02"/>
          <geom name="left_shin" fromto="-0.0087 -0.0027 -0.0796 -0.0350 -0.0109 -0.3184"  size=".05" density="1014"/>

          <body name="left_foot" pos="-0.0437 -0.0136 -0.3980">
            <joint name="left_ankle_x" pos="0 0 0" axis="1 0 0" range="-30 30" stiffness="400" damping="40" armature=".01"/>
            <joint name="left_ankle_y" pos="0 0 0" axis="0 1 0" range="-55 55" stiffness="400" damping="40" armature=".01"/>
            <joint name="left_ankle_z" pos="0 0 0" axis="0 0 1" range="-40 40" stiffness="400" damping="40" armature=".01"/>
            <!-- <geom name="left_foot" type="box" pos="0.0596 0.0132 -0.0279" size="0.0850 0.0483 0.0208" density="1141"/> -->
            <!-- <geom name="left_foot_toe" type="box" pos="0.1799 0.0132 -0.0288" size="0.0202 0.0478 0.0200" density="1141"/> -->
            <!-- <geom name="left_foot" type="mesh" mesh="left_foot_mesh" pos="0.0000 0.0000 0.0000" density="1141"/> -->
            <geom name="left_foot" type="box" pos="0.04736847 0.02286634 -0.03430487"  quat="0.99976203 0 0.02181489 0" size="0.10764448 0.04873052 0.03569894" density="1141"/>
          </body>
        </body>
      </body>
    </body>
  </worldbody>

  <actuator>
    <motor name='abdomen_x'       	gear='200' 	joint='abdomen_x'/>
    <motor name='abdomen_y'       	gear='200' 	joint='abdomen_y'/>
    <motor name='abdomen_z'       	gear='200' 	joint='abdomen_z'/>
    <motor name='neck_x'          	gear='50' 	joint='neck_x'/>
    <motor name='neck_y'            gear='50' 	joint='neck_y'/>
    <motor name='neck_z'           	gear='50' 	joint='neck_z'/>
    <motor name='right_shoulder_x' 	gear='100' 	joint='right_shoulder_x'/>
    <motor name='right_shoulder_y' 	gear='100' 	joint='right_shoulder_y'/>
    <motor name='right_shoulder_z' 	gear='100' 	joint='right_shoulder_z'/>
    <motor name='right_elbow'     	gear='70' 	joint='right_elbow'/>
    <motor name='left_shoulder_x' 	gear='100' 	joint='left_shoulder_x'/>
    <motor name='left_shoulder_y' 	gear='100' 	joint='left_shoulder_y'/>
    <motor name='left_shoulder_z' 	gear='100' 	joint='left_shoulder_z'/>
    <motor name='left_elbow'      	gear='70' 	joint='left_elbow'/>
    <motor name='right_hip_x'     	gear='200' 	joint='right_hip_x'/>
    <motor name='right_hip_z'     	gear='200' 	joint='right_hip_z'/>
    <motor name='right_hip_y'     	gear='200' 	joint='right_hip_y'/>
    <motor name='right_knee_x'      gear='150' 	joint='right_knee_x'/>
    <motor name='right_knee_y'      gear='150' 	joint='right_knee_y'/>
    <motor name='right_knee_z'      gear='150' 	joint='right_knee_z'/>
    <motor name='right_ankle_x'   	gear='90' 	joint='right_ankle_x'/>
    <motor name='right_ankle_y'   	gear='90' 	joint='right_ankle_y'/>
    <motor name='right_ankle_z'   	gear='90' 	joint='right_ankle_z'/>
    <motor name='left_hip_x'      	gear='200' 	joint='left_hip_x'/>
    <motor name='left_hip_z'      	gear='200' 	joint='left_hip_z'/>
    <motor name='left_hip_y'      	gear='200' 	joint='left_hip_y'/>
    <motor name='left_knee_x'       gear='150' 	joint='left_knee_x'/>
    <motor name='left_knee_y'       gear='150' 	joint='left_knee_y'/>
    <motor name='left_knee_z'       gear='150' 	joint='left_knee_z'/>
    <motor name='left_ankle_x'    	gear='90' 	joint='left_ankle_x'/>
    <motor name='left_ankle_y'    	gear='90' 	joint='left_ankle_y'/>
    <motor name='left_ankle_z'    	gear='90' 	joint='left_ankle_z'/>
  </actuator>

</mujoco>